<?xml version="1.0" encoding="utf-8"?>
<!-- This URDF was automatically created by SolidWorks to URDF Exporter! Originally created by Stephen Brawner (brawner@gmail.com) 
     Commit Version: 1.6.0-4-g7f85cfe  Build Version: 1.6.7995.38578
     For more information, please see http://wiki.ros.org/sw_urdf_exporter -->
<robot name="atom">
     <mujoco>
        <compiler 
        meshdir="package://atom_urdf/meshes/atom_p2/" 
        balanceinertia="true" 
        discardvisual="false" />
  </mujoco>
  
  <link name="world"></link>
  <joint name="floating_base_joint" type="floating">
    <parent link="world"/>
    <child link="pelvis"/>
  </joint>

  <link name="pelvis">
    <inertial>
      <origin xyz="0.0006 0.0000 -0.0998" rpy="0 0 0" />
      <mass value="6.5370" />
      <inertia ixx="0.0344" ixy="0.0000" ixz="0.0001" iyy="0.0292" iyz="0.0000" izz="0.0214" />
    </inertial>
    <visual>
      <origin xyz="0 0 0" rpy="0 0 0" />
      <geometry>
        <mesh filename="package://atom_urdf/meshes/atom_p2/pelvis.STL" />
      </geometry>
      <material name="">
        <color rgba="1 1 1 1" />
      </material>
    </visual>
    <!-- <collision>
      <origin xyz="0 0 0" rpy="0 0 0" />
      <geometry>
        <mesh filename="package://atom_urdf/meshes/atom_p2/pelvis.STL" />
      </geometry>
    </collision> -->
  </link>
  <link name="leg_l1_link">
    <inertial>
      <origin xyz="0.0011 0.0370 -0.0046" rpy="0 0 0" />
      <mass value="0.6084" />
      <inertia ixx="0.0010" ixy="-0.0001" ixz="0.0000" iyy="0.0015" iyz="0.0002" izz="0.0017" />
    </inertial>
    <visual>
      <origin xyz="0 0 0" rpy="0 0 0" />
      <geometry>
        <mesh filename="package://atom_urdf/meshes/atom_p2/leg_l1_link.STL" />
      </geometry>
      <material name="">
        <color rgba="1 1 1 1" />
      </material>
    </visual>
    <!-- <collision>
      <origin xyz="0 0 0" rpy="0 0 0" />
      <geometry>
        <mesh filename="package://atom_urdf/meshes/atom_p2/leg_l1_link.STL" />
      </geometry>
    </collision> -->
  </link>
  <joint name="leg_l1_joint" type="revolute">
    <origin xyz="0 0.0744999999999999 -0.133" rpy="0 0 0" />
    <parent link="pelvis" />
    <child link="leg_l1_link" />
    <axis xyz="0 1 0" />
    <limit lower="-2.5656" upper="3.0194" effort="1000" velocity="100" />
  </joint>
  <link name="leg_l2_link">
    <inertial>
      <origin xyz="-0.006 -0.0003 -0.0057" rpy="0 0 0" />
      <mass value="2.267" />
      <inertia ixx="0.0032" ixy="0.0000" ixz="0.0000" iyy="0.0033" iyz="-0.0001" izz="0.0030" />
    </inertial>
    <visual>
      <origin xyz="0 0 0" rpy="0 0 0" />
      <geometry>
        <mesh filename="package://atom_urdf/meshes/atom_p2/leg_l2_link.STL" />
      </geometry>
      <material name="">
        <color rgba="1 1 1 1" />
      </material>
    </visual>
    <!-- <collision>
      <origin xyz="0 0 0" rpy="0 0 0" />
      <geometry>
        <mesh filename="package://atom_urdf/meshes/atom_p2/leg_l2_link.STL" />
      </geometry>
  </collision> -->
  </link>
  <joint name="leg_l2_joint" type="revolute">
    <origin xyz="0.00283008034419562 0.0764999999999997 -0.0248392963919153" rpy="0 -0.113446401379624 0" />
    <parent link="leg_l1_link" />
    <child link="leg_l2_link" />
    <axis xyz="1 0 0" />
    <limit lower="-0.2618" upper="1.6581" effort="1000" velocity="100" />
  </joint>
  <link name="leg_l3_link">
    <inertial>
      <origin xyz="-0.0023 0.0113 -0.1214" rpy="0 0 0" />
      <mass value="5.5530" />
      <inertia ixx="0.0412" ixy="-0.0002" ixz="-0.0023" iyy="0.0416" iyz="0.0012" izz="0.0117" />
    </inertial>
    <visual>
      <origin xyz="0 0 0" rpy="0 0 0" />
      <geometry>
        <mesh filename="package://atom_urdf/meshes/atom_p2/leg_l3_link.STL" />
      </geometry>
      <material name="">
        <color rgba="1 1 1 1" />
      </material>
    </visual>
    <collision>
      <origin xyz="0 0 -0.12" rpy="0 0.113446401379624 0" />
      <geometry>
        <box size="0.08 0.08 0.24"/>
      </geometry>
    </collision>
  </link>
  <joint name="leg_l3_joint" type="revolute">
    <origin xyz="0 -0.0200000000000001 -0.065" rpy="0 0 0" />
    <parent link="leg_l2_link" />
    <child link="leg_l3_link" />
    <axis xyz="0 0 1" />
    <limit lower="-2.7925" upper="2.7925" effort="1000" velocity="100" />
  </joint>
  <link name="leg_l4_link">
    <inertial>
      <origin xyz="-0.0125 -0.0005 -0.1040" rpy="0 0 0" />
      <mass value="3.1000" />
      <inertia ixx="0.0189" ixy="0.0000" ixz="-0.0016" iyy="0.0189" iyz="0.0001" izz="0.0028" />
    </inertial>
    <visual>
      <origin xyz="0 0 0" rpy="0 0 0" />
      <geometry>
        <mesh filename="package://atom_urdf/meshes/atom_p2/leg_l4_link.STL" />
      </geometry>
      <material name="">
        <color rgba="1 1 1 1" />
      </material>
    </visual>
    <collision>
      <origin xyz="0 0 -0.16" rpy="0 0.113446401379624 0" />
      <geometry>
        <box size="0.08 0.08 0.32"/>
      </geometry>
    </collision>
  </link>
  <joint name="leg_l4_joint" type="revolute">
    <origin xyz="-0.0468661304999053 0 -0.3213387482501" rpy="0 0 0" />
    <parent link="leg_l3_link" />
    <child link="leg_l4_link" />
    <axis xyz="0 1 0" />
    <limit lower="0" upper="2.4871" effort="1000" velocity="100" />
  </joint>
  <link name="leg_l5_link">
    <inertial>
      <origin xyz="0.000091 0.000214 -0.013313" rpy="0 0 0" />
      <mass value="0.1552" />
      <inertia ixx="0.000042" ixy="0.0000" ixz="0.0000" iyy="0.000037" iyz="0.0000" izz="0.000023" />
    </inertial>
    <visual>
      <origin xyz="0 0 0" rpy="0 0 0" />
      <geometry>
        <mesh filename="package://atom_urdf/meshes/atom_p2/leg_l5_link.STL" />
      </geometry>
      <material name="">
        <color rgba="1 1 1 1" />
      </material>
    </visual>
    <!-- <collision>
      <origin xyz="0 0 0" rpy="0 0 0" />
      <geometry>
        <mesh filename="package://atom_urdf/meshes/atom_p2/leg_l5_link.STL" />
      </geometry>
    </collision> -->
  </link>
  <joint name="leg_l5_joint" type="revolute">
    <origin xyz="-0.031961645478192 0 -0.333525790934264" rpy="0 0.113446401379621 0" />
    <parent link="leg_l4_link" />
    <child link="leg_l5_link" />
    <axis xyz="0 1 0" />
    <limit lower="-0.8727" upper="0.5236" effort="1000" velocity="20" />
  </joint>
  <link name="leg_l6_link">
    <inertial>
      <origin xyz="0.0318 0.0000 -0.0352" rpy="0 0 0" />
      <mass value="0.6943" />
      <inertia ixx="0.0007" ixy="0.0000" ixz="0.0001" iyy="0.0032" iyz="0.0000" izz="0.0033" />
    </inertial>
    <visual>
      <origin xyz="0 0 0" rpy="0 0 0" />
      <geometry>
        <mesh filename="package://atom_urdf/meshes/atom_p2/leg_l6_link.STL" />
      </geometry>
      <material name="">
        <color rgba="1 1 1 1" />
      </material>
    </visual>
    <!-- <collision>
      <origin xyz="0 0 0" rpy="0 0 0" />
      <geometry>
        <mesh filename="package://atom_urdf/meshes/atom_p2/leg_l6_link.STL" />
      </geometry>
    </collision> -->
    <collision>
      <origin rpy="0 0 0" xyz="0.04 0 -0.056"/>
      <geometry>
        <box size="0.25 0.1 0.02"/>
      </geometry>
    </collision>
    <!-- <collision>
      <origin rpy="0 0 0" xyz="-0.025 0 -0.048"/>
      <geometry>
        <cylinder length = "0.02" radius = "0.035"/>
      </geometry>
    </collision>
    <collision>
      <origin rpy="0 0 0" xyz="0.13 0 -0.048"/>
      <geometry>
        <cylinder length = "0.02" radius = "0.032"/>
      </geometry>
    </collision> -->
  </link>
  <joint name="leg_l6_joint" type="revolute">
    <origin xyz="0 0 -0.025" rpy="0 0 0" />
    <parent link="leg_l5_link" />
    <child link="leg_l6_link" />
    <axis xyz="1 0 0" />
    <limit lower="-0.48" upper="0.48" effort="1000" velocity="20" />
  </joint>
  <link name="leg_r1_link">
    <inertial>
      <origin xyz="0.0011 -0.0370 -0.0046" rpy="0 0 0" />
      <mass value="0.6084" />
      <inertia ixx="0.0010" ixy="0.0001" ixz="0.0000" iyy="0.0015" iyz="-0.0002" izz="0.0017" />
    </inertial>
    <visual>
      <origin xyz="0 0 0" rpy="0 0 0" />
      <geometry>
        <mesh filename="package://atom_urdf/meshes/atom_p2/leg_r1_link.STL" />
      </geometry>
      <material name="">
        <color rgba="1 1 1 1" />
      </material>
    </visual>
    <!-- <collision>
      <origin xyz="0 0 0" rpy="0 0 0" />
      <geometry>
        <mesh filename="package://atom_urdf/meshes/atom_p2/leg_r1_link.STL" />
      </geometry>
    </collision> -->
  </link>
  <joint name="leg_r1_joint" type="revolute">
    <origin xyz="0 -0.0745000000000004 -0.133" rpy="0 0 0" />
    <parent link="pelvis" />
    <child link="leg_r1_link" />
    <axis xyz="0 1 0" />
    <limit lower="-2.5656" upper="3.0194" effort="1000" velocity="100" />
  </joint>
  <link name="leg_r2_link">
    <inertial>
      <origin xyz="-0.006 0.0003 -0.0057" rpy="0 0 0" />
      <mass value="2.267" />
      <inertia ixx="0.0032" ixy="0.0000" ixz="0.0000" iyy="0.0033" iyz="0.0001" izz="0.0030" />
    </inertial>
    <visual>
      <origin xyz="0 0 0" rpy="0 0 0" />
      <geometry>
        <mesh filename="package://atom_urdf/meshes/atom_p2/leg_r2_link.STL" />
      </geometry>
      <material name="">
        <color rgba="1 1 1 1" />
      </material>
    </visual>
    <!-- <collision>
      <origin xyz="0 0 0" rpy="0 0 0" />
      <geometry>
        <mesh filename="package://atom_urdf/meshes/atom_p2/leg_r2_link.STL" />
      </geometry>
    </collision> -->
  </link>
  <joint name="leg_r2_joint" type="revolute">
    <origin xyz="0.00283008034422469 -0.0764999999994626 -0.0248392963919156" rpy="0 -0.113446401379617 0" />
    <parent link="leg_r1_link" />
    <child link="leg_r2_link" />
    <axis xyz="1 0 0" />
    <limit lower="-1.6581" upper="0.2618" effort="1000" velocity="100" />
  </joint>
  <link name="leg_r3_link">
    <inertial>
      <origin xyz="-0.0023 -0.0113 -0.1214" rpy="0 0 0" />
      <mass value="5.5530" />
      <inertia ixx="0.0412" ixy="0.0002" ixz="-0.0023" iyy="0.0416" iyz="-0.0012" izz="0.0117" />
    </inertial>
    <visual>
      <origin xyz="0 0 0" rpy="0 0 0" />
      <geometry>
        <mesh filename="package://atom_urdf/meshes/atom_p2/leg_r3_link.STL" />
      </geometry>
      <material name="">
        <color rgba="1 1 1 1" />
      </material>
    </visual>
    <collision>
      <origin xyz="0 0 -0.12" rpy="0 0.113446401379624 0" />
      <geometry>
        <box size="0.08 0.08 0.24"/>
      </geometry>
    </collision>
  </link>
  <joint name="leg_r3_joint" type="revolute">
    <origin xyz="0 0.0200000000000017 -0.0649999999999998" rpy="0 0 0" />
    <parent link="leg_r2_link" />
    <child link="leg_r3_link" />
    <axis xyz="0 0 1" />
    <limit lower="-2.7925" upper="2.7925" effort="1000" velocity="20" />
  </joint>
  <link name="leg_r4_link">
    <inertial>
      <origin xyz="-0.0125 0.0005 -0.1040" rpy="0 0 0" />
      <mass value="3.1000" />
      <inertia ixx="0.0189" ixy="0.0000" ixz="-0.0016" iyy="0.0189" iyz="-0.0001" izz="0.0028" />
    </inertial>
    <visual>
      <origin xyz="0 0 0" rpy="0 0 0" />
      <geometry>
        <mesh filename="package://atom_urdf/meshes/atom_p2/leg_r4_link.STL" />
      </geometry>
      <material name="">
        <color rgba="1 1 1 1" />
      </material>
    </visual>
    <collision>
      <origin xyz="0 0 -0.16" rpy="0 0.113446401379624 0" />
      <geometry>
        <box size="0.08 0.08 0.32"/>
      </geometry>
    </collision>
  </link>
  <joint name="leg_r4_joint" type="revolute">
    <origin xyz="-0.0468661304149304 0 -0.321338748280348" rpy="0 0 0" />
    <parent link="leg_r3_link" />
    <child link="leg_r4_link" />
    <axis xyz="0 1 0" />
    <limit lower="0" upper="2.4871" effort="1000" velocity="100" />
  </joint>
  <link name="leg_r5_link">
    <inertial>
      <origin xyz="0.000091 0.000214 -0.013313" rpy="0 0 0" />
      <mass value="0.1552" />
      <inertia ixx="0.000042" ixy="0.0000" ixz="0.0000" iyy="0.000037" iyz="0.0000" izz="0.000023" />
    </inertial>
    <visual>
      <origin xyz="0 0 0" rpy="0 0 0" />
      <geometry>
        <mesh filename="package://atom_urdf/meshes/atom_p2/leg_r5_link.STL" />
      </geometry>
      <material name="">
        <color rgba="1 1 1 1" />
      </material>
    </visual>
    <!-- <collision>
      <origin xyz="0 0 0" rpy="0 0 0" />
      <geometry>
        <mesh filename="package://atom_urdf/meshes/atom_p2/leg_r5_link.STL" />
      </geometry>
    </collision> -->
  </link>
  <joint name="leg_r5_joint" type="revolute">
    <origin xyz="-0.0319616454782119 0 -0.333525790934262" rpy="0 0.113446401379635 0" />
    <parent link="leg_r4_link" />
    <child link="leg_r5_link" />
    <axis xyz="0 1 0" />
    <limit lower="-0.8727" upper="0.5236" effort="1000" velocity="100" />
  </joint>
  <link name="leg_r6_link">
    <inertial>
      <origin xyz="0.03180 -0.00000 -0.0352" rpy="0 0 0" />
      <mass value="0.6943" />
      <inertia ixx="0.0007" ixy="0.0000" ixz="0.0001" iyy="0.0032" iyz="0.0000" izz="0.0033" />
    </inertial>
    <visual>
      <origin xyz="0 0 0" rpy="0 0 0" />
      <geometry>
        <mesh filename="package://atom_urdf/meshes/atom_p2/leg_r6_link.STL" />
      </geometry>
      <material name="">
        <color rgba="1 1 1 1" />
      </material>
    </visual>
    <!-- <collision>
      <origin xyz="0 0 0" rpy="0 0 0" />
      <geometry>
        <mesh filename="package://atom_urdf/meshes/atom_p2/leg_r6_link.STL" />
      </geometry>
    </collision> -->
    <collision>
      <origin rpy="0 0 0" xyz="0.04 0 -0.056"/>
      <geometry>
        <box size="0.25 0.1 0.02"/>
      </geometry>
    </collision>
    <!-- <collision>
      <origin rpy="0 0 0" xyz="-0.025 0 -0.048"/>
      <geometry>
        <cylinder length = "0.02" radius = "0.035"/>
      </geometry>
    </collision> -->
    <!-- <collision>
      <origin rpy="0 0 0" xyz="0.13 0 -0.048"/>
      <geometry>
        <cylinder length = "0.02" radius = "0.032"/>
      </geometry>
    </collision> -->
  </link>
  <joint name="leg_r6_joint" type="revolute">
    <origin xyz="0 0 -0.025" rpy="0 0 0" />
    <parent link="leg_r5_link" />
    <child link="leg_r6_link" />
    <axis xyz="1 0 0" />
    <limit lower="-0.48" upper="0.48" effort="1000" velocity="100" />
  </joint>
  <link name="torso_link">
    <inertial>
      <!-- <origin xyz="-0.0116 0 0.2190" rpy="0 0 0" />
      <mass value="14.0858" />
      <inertia ixx="0.2105" ixy="0.0000" ixz="0.0000" iyy="0.1880" iyz="0.0000" izz="0.1030" /> -->
      <origin xyz="-0.0155931 0 0.2199051" rpy="0 0 0" />
      <mass value="14.0858" />
      <inertia ixx="0.1671325" ixy="0.0000" ixz="-0.0005474" iyy="0.1806563" iyz="0.0000" izz="0.0672070" />
    </inertial>
    <visual>
      <origin xyz="0 0 0" rpy="0 0 0" />
      <geometry>
        <mesh filename="package://atom_urdf/meshes/atom_p2/torso_link.STL" />
      </geometry>
      <material name="">
        <color rgba="1 1 1 1" />
      </material>
    </visual>
    <collision>
      <origin xyz="0 0 0.2" rpy="0 0 0" />
      <geometry>
        <box size="0.26 0.24 0.4"/>
      </geometry>
    </collision>
  </link>
  <joint name="torso_joint" type="revolute">
    <origin xyz="0 0 0" rpy="0 0 0" />
    <parent link="pelvis" />
    <child link="torso_link" />
    <axis xyz="0 0 1" />
    <limit lower="-2.7925" upper="2.7925" effort="1000" velocity="100" />
  </joint>
  <link name="left_shoulder_pitch_link">
    <inertial>
      <origin xyz="0.0044 0.0368 0.0000" rpy="0 0 0" />
      <mass value="0.4473" />
      <inertia ixx="0.0007" ixy="0.0001" ixz="-0.0001" iyy="0.0008" iyz="0.0000" izz="0.0010" />
    </inertial>
    <visual>
      <origin xyz="0 0 0" rpy="0 0 0" />
      <geometry>
        <mesh filename="package://atom_urdf/meshes/atom_p2/left_shoulder_pitch_link.STL" />
      </geometry>
      <material name="">
        <color rgba="1 1 1 1" />
      </material>
    </visual>
    <!-- <collision>
      <origin xyz="0 0 0" rpy="0 0 0" />
      <geometry>
        <mesh filename="package://atom_urdf/meshes/atom_p2/left_shoulder_pitch_link.STL" />
      </geometry>
    </collision> -->
  </link>
  <joint name="left_shoulder_pitch_joint" type="revolute">
    <origin xyz="0 0.128 0.333" rpy="0 0 0" />
    <parent link="torso_link" />
    <child link="left_shoulder_pitch_link" />
    <axis xyz="0 1 0" />
    <limit lower="-2.97" upper="2.97" effort="56" velocity="2.62" />
  </joint>
  <link name="left_shoulder_roll_link">
    <inertial>
      <origin xyz="0.0124 0.0009 -0.0545" rpy="0 0 0" />
      <mass value="1.7940" />
      <inertia ixx="0.0066" ixy="0.0000" ixz="0.0004" iyy="0.0067" iyz="0.0000" izz="0.0013" />
    </inertial>
    <visual>
      <origin xyz="0 0 0" rpy="0 0 0" />
      <geometry>
        <mesh filename="package://atom_urdf/meshes/atom_p2/left_shoulder_roll_link.STL" />
      </geometry>
      <material name="">
        <color rgba="1 1 1 1" />
      </material>
    </visual>
    <collision>
      <origin xyz="0 0 -0.1" rpy="0 0 0" />
      <geometry>
        <box size="0.06 0.06 0.24"/>
      </geometry>
    </collision>
  </link>
  <joint name="left_shoulder_roll_joint" type="revolute">
    <origin xyz="0 0.0780000000000016 0" rpy="0.18 0 0" />
    <parent link="left_shoulder_pitch_link" />
    <child link="left_shoulder_roll_link" />
    <axis xyz="1 0 0" />
    <limit lower="-0.43" upper="3.14" effort="36" velocity="2.62" />
  </joint>
  <link name="left_shoulder_yaw_link">
    <inertial>
      <origin xyz="-0.0014 0.0066 -0.1179" rpy="0 0 0" />
      <mass value="0.9798" />
      <inertia ixx="0.0018" ixy="0.0000" ixz="-0.0001" iyy="0.0016" iyz="-0.0001" izz="0.0008" />
    </inertial>
    <visual>
      <origin xyz="0 0 0" rpy="0 0 0" />
      <geometry>
        <mesh filename="package://atom_urdf/meshes/atom_p2/left_shoulder_yaw_link.STL" />
      </geometry>
      <material name="">
        <color rgba="1 1 1 1" />
      </material>
    </visual>
    <!-- <collision>
      <origin xyz="0 0 0" rpy="0 0 0" />
      <geometry>
        <mesh filename="package://atom_urdf/meshes/atom_p2/left_shoulder_yaw_link.STL" />
      </geometry>
    </collision> -->
  </link>
  <joint name="left_shoulder_yaw_joint" type="revolute">
    <origin xyz="0 0 -0.135" rpy="0 0 0" />
    <parent link="left_shoulder_roll_link" />
    <child link="left_shoulder_yaw_link" />
    <axis xyz="0 0 1" />
    <limit lower="-2.97" upper="2.97" effort="36" velocity="2.62" />
  </joint>
  <link name="left_elbow_pitch_link">
    <inertial>
      <origin xyz="0.0903 0.0016 -0.0003" rpy="0 0 0" />
      <mass value="0.8548" />
      <inertia ixx="0.0008" ixy="-0.0001" ixz="0.0000" iyy="0.0025" iyz="0.0000" izz="0.0028" />
    </inertial>
    <visual>
      <origin xyz="0 0 0" rpy="0 0 0" />
      <geometry>
        <mesh filename="package://atom_urdf/meshes/atom_p2/left_elbow_pitch_link.STL" />
      </geometry>
      <material name="">
        <color rgba="1 1 1 1" />
      </material>
    </visual>
    <collision>
      <origin xyz="0.16 0 0" rpy="0 0 0" />
      <geometry>
        <box size="0.30 0.06 0.06"/>
      </geometry>
    </collision>
  </link>
  <joint name="left_elbow_pitch_joint" type="revolute">
    <origin xyz="0.00044198773719138 0 -0.130000000000198" rpy="0 0 0" />
    <parent link="left_shoulder_yaw_link" />
    <child link="left_elbow_pitch_link" />
    <axis xyz="0 1 0" />
    <limit lower="-1.57" upper="2" effort="36" velocity="2.62" />
  </joint>
  <link name="left_elbow_roll_link">
    <inertial>
      <origin xyz="0.0270 0.0018 -0.0002" rpy="0 0 0" />
      <mass value="0.2126" />
      <inertia ixx="0.0003" ixy="0.0000" ixz="0.0000" iyy="0.0002" iyz="0.0000" izz="0.0003" />
    </inertial>
    <visual>
      <origin xyz="0 0 0" rpy="0 0 0" />
      <geometry>
        <mesh filename="package://atom_urdf/meshes/atom_p2/left_elbow_roll_link.STL" />
      </geometry>
      <material name="">
        <color rgba="1 1 1 1" />
      </material>
    </visual>
    <!-- <collision>
      <origin xyz="0 0 0" rpy="0 0 0" />
      <geometry>
        <mesh filename="package://atom_urdf/meshes/atom_p2/left_elbow_roll_link.STL" />
      </geometry>
    </collision> -->
  </link>
  <joint name="left_elbow_roll_joint" type="revolute">
    <origin xyz="0.1453 0 0" rpy="0 0 0" />
    <parent link="left_elbow_pitch_link" />
    <child link="left_elbow_roll_link" />
    <axis xyz="1 0 0" />
    <limit lower="-2.97" upper="2.97" effort="18.6" velocity="2.62" />
  </joint>
  <link name="left_wrist_pitch_link">
    <inertial>
      <origin xyz="0.0421 -0.0042 -0.0038" rpy="0 0 0" />
      <mass value="1.2573" />
      <inertia ixx="0.0008" ixy="0.0002" ixz="-0.0002" iyy="0.0029" iyz="0.0000" izz="0.0029" />
    </inertial>
    <visual>
      <origin xyz="0 0 0" rpy="0 0 0" />
      <geometry>
        <mesh filename="package://atom_urdf/meshes/atom_p2/left_wrist_pitch_link.STL" />
      </geometry>
      <material name="">
        <color rgba="1 1 1 1" />
      </material>
    </visual>
    <!-- <collision>
      <origin xyz="0 0 0" rpy="0 0 0" />
      <geometry>
        <mesh filename="package://atom_urdf/meshes/atom_p2/left_wrist_pitch_link.STL" />
      </geometry>
    </collision> -->
  </link>
  <joint name="left_wrist_pitch_joint" type="revolute">
    <origin xyz="0.0534500000207669 0 0" rpy="0 0 0" />
    <parent link="left_elbow_roll_link" />
    <child link="left_wrist_pitch_link" />
    <axis xyz="0 1 0" />
    <limit lower="-1.57" upper="1.57" effort="18.6" velocity="2.62" />
  </joint>
  <link name="left_wrist_yaw_link">
    <inertial>
      <origin xyz="0.0290 0.0004 0.0010" rpy="0 0 0" />
      <mass value="0.3340" />
      <inertia ixx="0.0003" ixy="0.0000" ixz="0.0000" iyy="0.0004" iyz="0.0000" izz="0.0003" />
    </inertial>
    <visual>
      <origin xyz="0 0 0" rpy="0 0 0" />
      <geometry>
        <mesh filename="package://atom_urdf/meshes/atom_p2/left_wrist_yaw_link.STL" />
      </geometry>
      <material name="">
        <color rgba="1 1 1 1" />
      </material>
    </visual>
    <!-- <collision>
      <origin xyz="0 0 0" rpy="0 0 0" />
      <geometry>
        <mesh filename="package://atom_urdf/meshes/atom_p2/left_wrist_yaw_link.STL" />
      </geometry>
    </collision> -->
  </link>
  <joint name="left_wrist_yaw_joint" type="revolute">
    <origin xyz="0.085 0 0" rpy="0 0 0" />
    <parent link="left_wrist_pitch_link" />
    <child link="left_wrist_yaw_link" />
    <axis xyz="0 0 0.999999999999887" />
    <limit lower="-1.57" upper="1.57" effort="18.6" velocity="2.62" />
  </joint>
  <link name="right_shoulder_pitch_link">
    <inertial>
      <origin xyz="0.0044 -0.0368 0.0000" rpy="0 0 0" />
      <mass value="0.4473" />
      <inertia ixx="0.0007" ixy="-0.0001" ixz="-0.0001" iyy="0.0008" iyz="0.0000" izz="0.0010" />
    </inertial>
    <visual>
      <origin xyz="0 0 0" rpy="0 0 0" />
      <geometry>
        <mesh filename="package://atom_urdf/meshes/atom_p2/right_shoulder_pitch_link.STL" />
      </geometry>
      <material name="">
        <color rgba="1 1 1 1" />
      </material>
    </visual>
    <!-- <collision>
      <origin xyz="0 0 0" rpy="0 0 0" />
      <geometry>
        <mesh filename="package://atom_urdf/meshes/atom_p2/right_shoulder_pitch_link.STL" />
      </geometry>
    </collision> -->
  </link>
  <joint name="right_shoulder_pitch_joint" type="revolute">
    <origin xyz="0 -0.128 0.333" rpy="0 0 0" />
    <parent link="torso_link" />
    <child link="right_shoulder_pitch_link" />
    <axis xyz="0 1 0" />
    <limit lower="-2.97" upper="2.97" effort="56" velocity="2.62" />
  </joint>
  <link name="right_shoulder_roll_link">
    <inertial>
      <origin xyz="0.0124 -0.0009 -0.0545" rpy="0 0 0" />
      <mass value="1.7940" />
      <inertia ixx="0.0066" ixy="0.0000" ixz="0.0004" iyy="0.0067" iyz="0.0000" izz="0.0013" />
    </inertial>
    <visual>
      <origin xyz="0 0 0" rpy="0 0 0" />
      <geometry>
        <mesh filename="package://atom_urdf/meshes/atom_p2/right_shoulder_roll_link.STL" />
      </geometry>
      <material name="">
        <color rgba="1 1 1 1" />
      </material>
    </visual>
    <collision>
      <origin xyz="0 0 -0.1" rpy="0 0 0" />
      <geometry>
        <box size="0.06 0.06 0.24"/>
      </geometry>
    </collision>
  </link>
  <joint name="right_shoulder_roll_joint" type="revolute">
    <origin xyz="0 -0.078 0" rpy="-0.18 0 0" />
    <parent link="right_shoulder_pitch_link" />
    <child link="right_shoulder_roll_link" />
    <axis xyz="1 0 0" />
    <limit lower="-3.14" upper="0.43" effort="36" velocity="2.62" />
  </joint>
  <link name="right_shoulder_yaw_link">
    <inertial>
      <origin xyz="-0.0014 -0.0066 -0.1179" rpy="0 0 0" />
      <mass value="0.9798" />
      <inertia ixx="0.0018" ixy="0.0000" ixz="-0.0001" iyy="0.0016" iyz="0.0001" izz="0.0008" />
    </inertial>
    <visual>
      <origin xyz="0 0 0" rpy="0 0 0" />
      <geometry>
        <mesh filename="package://atom_urdf/meshes/atom_p2/right_shoulder_yaw_link.STL" />
      </geometry>
      <material name="">
        <color rgba="1 1 1 1" />
      </material>
    </visual>
    <!-- <collision>
      <origin xyz="0 0 0" rpy="0 0 0" />
      <geometry>
        <mesh filename="package://atom_urdf/meshes/atom_p2/right_shoulder_yaw_link.STL" />
      </geometry>
    </collision> -->
  </link>
  <joint name="right_shoulder_yaw_joint" type="revolute">
    <origin xyz="0 0 -0.135" rpy="0 0 0" />
    <parent link="right_shoulder_roll_link" />
    <child link="right_shoulder_yaw_link" />
    <axis xyz="0 0 1" />
    <limit lower="-2.97" upper="2.97" effort="36" velocity="2.62" />
  </joint>
  <link name="right_elbow_pitch_link">
    <inertial>
      <origin xyz="0.0903 -0.0016 -0.0003" rpy="0 0 0" />
      <mass value="0.8548" />
      <inertia ixx="0.0008" ixy="0.0001" ixz="0.0000" iyy="0.0025" iyz="-0.0000" izz="0.0028" />
    </inertial>
    <visual>
      <origin xyz="0 0 0" rpy="0 0 0" />
      <geometry>
        <mesh filename="package://atom_urdf/meshes/atom_p2/right_elbow_pitch_link.STL" />
      </geometry>
      <material name="">
        <color rgba="1 1 1 1" />
      </material>
    </visual>
    <collision>
      <origin xyz="0.16 0 0" rpy="0 0 0" />
      <geometry>
        <box size="0.30 0.06 0.06"/>
      </geometry>
    </collision>
  </link>
  <joint name="right_elbow_pitch_joint" type="revolute">
    <origin xyz="0.000441987737191488 0 -0.130000000000198" rpy="0 0 0" />
    <parent link="right_shoulder_yaw_link" />
    <child link="right_elbow_pitch_link" />
    <axis xyz="0 1 0" />
    <limit lower="-1.57" upper="2" effort="36" velocity="2.62" />
  </joint>
  <link name="right_elbow_roll_link">
    <inertial>
      <origin xyz="0.0270 -0.0018 -0.0002" rpy="0 0 0" />
      <mass value="0.2126" />
      <inertia ixx="0.0003" ixy="0.0000" ixz="0.0000" iyy="0.0002" iyz="0.0000" izz="0.0003" />
    </inertial>
    <visual>
      <origin xyz="0 0 0" rpy="0 0 0" />
      <geometry>
        <mesh filename="package://atom_urdf/meshes/atom_p2/right_elbow_roll_link.STL" />
      </geometry>
      <material name="">
        <color rgba="1 1 1 1" />
      </material>
    </visual>
    <!-- <collision>
      <origin xyz="0 0 0" rpy="0 0 0" />
      <geometry>
        <mesh filename="package://atom_urdf/meshes/atom_p2/right_elbow_roll_link.STL" />
      </geometry>
    </collision> -->
  </link>
  <joint name="right_elbow_roll_joint" type="revolute">
    <origin xyz="0.145293702343308 0 0" rpy="0 0 0" />
    <parent link="right_elbow_pitch_link" />
    <child link="right_elbow_roll_link" />
    <axis xyz="1 0 0" />
    <limit lower="-2.97" upper="2.97" effort="18.6" velocity="2.62" />
  </joint>
  <link name="right_wrist_pitch_link">
    <inertial>
      <origin xyz="0.0421 0.0042 -0.0038" rpy="0 0 0" />
      <mass value="1.2573" />
      <inertia ixx="0.0008" ixy="-0.0002" ixz="-0.0002" iyy="0.0029" iyz="0.0000" izz="0.0029" />
    </inertial>
    <visual>
      <origin xyz="0 0 0" rpy="0 0 0" />
      <geometry>
        <mesh filename="package://atom_urdf/meshes/atom_p2/right_wrist_pitch_link.STL" />
      </geometry>
      <material name="">
        <color rgba="1 1 1 1" />
      </material>
    </visual>
    <!-- <collision>
      <origin xyz="0 0 0" rpy="0 0 0" />
      <geometry>
        <mesh filename="package://atom_urdf/meshes/atom_p2/right_wrist_pitch_link.STL" />
      </geometry>
    </collision> -->
  </link>
  <joint name="right_wrist_pitch_joint" type="revolute">
    <origin xyz="0.0534499999999523 0 0" rpy="0 0 0" />
    <parent link="right_elbow_roll_link" />
    <child link="right_wrist_pitch_link" />
    <axis xyz="0 1 0" />
    <limit lower="-1.57" upper="1.57" effort="18.6" velocity="2.62" />
  </joint>
  <link name="right_wrist_yaw_link">
    <inertial>
      <origin xyz="0.0290 -0.0004 0.0010" rpy="0 0 0" />
      <mass value="0.3340" />
      <inertia ixx="0.0003" ixy="0.0000" ixz="0.0000" iyy="0.0004" iyz="-0.0000" izz="0.0003" />
    </inertial>
    <visual>
      <origin xyz="0 0 0" rpy="0 0 0" />
      <geometry>
        <mesh filename="package://atom_urdf/meshes/atom_p2/right_wrist_yaw_link.STL" />
      </geometry>
      <material name="">
        <color rgba="1 1 1 1" />
      </material>
    </visual>
    <!-- <collision>
      <origin xyz="0 0 0" rpy="0 0 0" />
      <geometry>
        <mesh filename="package://atom_urdf/meshes/atom_p2/right_wrist_yaw_link.STL" />
      </geometry>
    </collision> -->
  </link>
  <joint name="right_wrist_yaw_joint" type="revolute">
    <origin xyz="0.085 0 0" rpy="0 0 0" />
    <parent link="right_wrist_pitch_link" />
    <child link="right_wrist_yaw_link" />
    <axis xyz="0 0 1" />
    <limit lower="-1.57" upper="1.57" effort="18.6" velocity="2.62" />
  </joint>
  <link name="head_yaw_link">
    <inertial>
      <origin xyz="0.0000 -0.0027 0.0383" rpy="0 0 0" />
      <mass value="0.4387" />
      <inertia ixx="0.0003" ixy="0.0000" ixz="0.0000" iyy="0.0002" iyz="0.0000" izz="0.0002" />
    </inertial>
    <visual>
      <origin xyz="0 0 0" rpy="0 0 0" />
      <geometry>
        <mesh filename="package://atom_urdf/meshes/atom_p2/head_yaw_link.STL" />
      </geometry>
      <material name="">
        <color rgba="1 1 1 1" />
      </material>
    </visual>
    <!-- <collision>
      <origin xyz="0 0 0" rpy="0 0 0" />
      <geometry>
        <mesh filename="package://atom_urdf/meshes/atom_p2/head_yaw_link.STL" />
      </geometry>
    </collision> -->
  </link>
  <joint name="head_yaw_joint" type="revolute">
    <origin xyz="0 0 0.4177" rpy="0 0 0" />
    <parent link="torso_link" />
    <child link="head_yaw_link" />
    <axis xyz="0 0 1" />
    <limit lower="-1.57" upper="1.57" effort="12" velocity="6.28" />
  </joint>
  <link name="head_pitch_link">
    <inertial>
      <origin xyz="0.0337 0.0004 0.1204" rpy="0 0 0" />
      <mass value="1.3341" />
      <inertia ixx="0.0042" ixy="0.0000" ixz="0.0001" iyy="0.0070" iyz="0.0000" izz="0.0067" />
    </inertial>
    <visual>
      <origin xyz="0 0 0" rpy="0 0 0" />
      <geometry>
        <mesh filename="package://atom_urdf/meshes/atom_p2/head_pitch_link.STL" />
      </geometry>
      <material name="">
        <color rgba="1 1 1 1" />
      </material>
    </visual>
    <collision>
      <origin xyz="0.05 0 0.1" rpy="0 0 0" />
      <geometry>
        <!-- <mesh filename="package://atom_urdf/meshes/atom_p2/head_pitch_link.STL" /> -->
        <box size="0.16 0.14 0.14"/>
      </geometry>
    </collision>
  </link>
  <joint name="head_pitch_joint" type="revolute">
    <origin xyz="0 0 0.0" rpy="0 0 0" />
    <parent link="head_yaw_link" />
    <child link="head_pitch_link" />
    <axis xyz="0 1 0" />
    <limit lower="-1.57" upper="0.6981" effort="12" velocity="6.28" />
  </joint>

  <!-- imu -->
  <link name="imu_link">
  </link>
  <joint name="imu_joint" type="fixed">
    <origin xyz="0 0 -0.18" rpy="0 0 0" />
    <parent link="torso_link" />
    <child link="imu_link" />
  </joint>

</robot>
